<?xml version="1.0"?>
<robot xmlns:xacro="http://www.ros.org/wiki/xacro">

    <xacro:include filename="inertial_macros.xacro"/>

    <!-- links and joints go here -->

    <!-- The rest of the robot can be described from base_link, which is the centre point of the three driving wheels -->
    <link name="base_link">
    </link>

    <!-- chassis joint goes here. It connects chassis to base_link via fixed joint -->
    <joint name="chassis_joint" type="fixed">
        <parent link="base_link"/>
        <child link="chassis"/>
        <origin xyz="0 0 0"/>
    </joint>

    <!-- chassis description goes here -->
    <link name="chassis">
        <visual>
            <geometry>
                <!-- This works in Rviz -->
                <!-- <mesh filename="package://robocap_sim/urdf/frame_ultra_low_poly.stl" scale="0.001 0.001 0.001"/> -->
                <!-- This works in gazebo -->
                <mesh filename="$(find robocap_sim)/urdf/frame_ultra_low_poly.stl" scale="0.001 0.001 0.001"/>
            </geometry>
            <material name="white"/>
        </visual>
        <!-- physics model -->
        <collision>
            <origin xyz="0 0 0.77" rpy="0 0 0"/>
            <geometry>
                <cylinder length="1.54" radius="0.25"/>
            </geometry>
        </collision>
        <xacro:inertial_cylinder mass="20" length="1.54" radius="0.25">
            <origin xyz="0 0 0.77" rpy="0 0 0"/>
        </xacro:inertial_cylinder>
    </link>

    <joint name="laser_joint" type="fixed">
        <parent link="chassis"/>
        <child link="laser"/>
        <origin xyz="0 0 0.07" rpy="0 0 0"/>
    </joint>
    <link name="laser">
        <visual>
            <origin xyz="0 0 0" rpy="0 0 0"/>
            <geometry>
                <cylinder length="0.05" radius="0.05"/>
            </geometry>
            <material name="black"/>
        </visual>
    </link>

    <!-- gazebo specific description -->
    <gazebo reference="chassis">
        <material>Gazebo/White</material>
    </gazebo>

    <!-- WHEEL 1 (CLOCKWISE) -->
    <joint name="wheel_1_joint" type="continuous">
        <parent link="base_link"/>
        <child link="wheel_1"/>
        <origin xyz="0.2 0 0" rpy="0 -${pi/2} 0"/>
        <axis xyz="0 0 1"/>
    </joint>

    <link name="wheel_1">
        <visual>
            <geometry>      
                <cylinder length="0.038" radius="0.05" />
            </geometry>
            <material name="black"/>
        </visual>
        <collision>
            <geometry>      
                <cylinder length="0.038" radius="0.05" />
            </geometry>
        </collision>
        <xacro:inertial_cylinder mass="0.2" length="0.038" radius="0.05">
            <origin xyz="0 0 0" rpy="0 0 0"/>
        </xacro:inertial_cylinder>
    </link>

    <gazebo reference="wheel_1">
        <material>Gazebo/Black</material>
        <mu1>0.2</mu1>
        <mu2>1.5</mu2>
        <kp>10000000.0</kp>
        <kd>10000.0</kd>
        <fdir1>0 0 1</fdir1>
        <maxContacts>1</maxContacts>
    </gazebo>

    <!-- WHEEL 2 -->
    <joint name="wheel_2_joint" type="continuous">
        <parent link="base_link"/>
        <child link="wheel_2"/>
        <origin xyz="-0.1 -0.1732050808 0" rpy="0 ${pi/2} ${pi/3}"/>
        <axis xyz="0 0 1"/>
    </joint>

    <link name="wheel_2">
        <visual>
            <geometry>      
                <cylinder length="0.038" radius="0.05" />
            </geometry>
            <material name="black"/>
        </visual>
        <collision>
            <geometry>      
                <cylinder length="0.038" radius="0.05" />
            </geometry>
        </collision>
        <xacro:inertial_cylinder mass="0.2" length="0.038" radius="0.05">
            <origin xyz="0 0 0" rpy="0 0 0"/>
        </xacro:inertial_cylinder>
    </link>

    <gazebo reference="wheel_2">
        <material>Gazebo/Black</material>
        <mu1>0.2</mu1>
        <mu2>1.5</mu2>
        <kp>10000000.0</kp>
        <kd>10000.0</kd>
        <fdir1>0 0 1</fdir1>
        <maxContacts>1</maxContacts>
    </gazebo>

    <!-- WHEEL 3 -->
    <joint name="wheel_3_joint" type="continuous">
        <parent link="base_link"/>
        <child link="wheel_3"/>
        <origin xyz="-0.1 0.1732050808 0" rpy="0 ${pi/2} -${pi/3}"/>
        <axis xyz="0 0 1"/>
    </joint>

    <link name="wheel_3">
        <visual>
            <geometry>      
                <cylinder length="0.038" radius="0.05" />
            </geometry>
            <material name="black"/>
        </visual>
        <collision>
            <geometry>      
                <cylinder length="0.038" radius="0.05" />
            </geometry>
        </collision>
        <xacro:inertial_cylinder mass="0.2" length="0.038" radius="0.05">
            <origin xyz="0 0 0" rpy="0 0 0"/>
        </xacro:inertial_cylinder>
    </link>

    <gazebo reference="wheel_3">
        <material>Gazebo/Black</material>
        <mu1>0.2</mu1>
        <mu2>1.5</mu2>
        <kp>10000000.0</kp>
        <kd>10000.0</kd>
        <fdir1>0 0 1</fdir1>
        <maxContacts>1</maxContacts>
    </gazebo>

    <!-- Transmissions -->
    <transmission name="tran1">
        <type>transmission_interface/SimpleTransmission</type>
        <joint name="wheel_1_joint">
            <hardwareInterface>hardware_interface/ActuatorInterface</hardwareInterface>
        </joint>
        <actuator name="motor_1">
            <hardwareInterface>hardware_interface/ActuatorInterface</hardwareInterface>
            <mechanicalReduction>1</mechanicalReduction>
        </actuator>
    </transmission>

    <transmission name="tran2">
        <type>transmission_interface/SimpleTransmission</type>
        <joint name="wheel_2_joint">
            <hardwareInterface>hardware_interface/ActuatorInterface</hardwareInterface>
        </joint>
        <actuator name="motor_2">
            <hardwareInterface>hardware_interface/ActuatorInterface</hardwareInterface>
            <mechanicalReduction>1</mechanicalReduction>
        </actuator>
    </transmission>

    <transmission name="tran3">
        <type>transmission_interface/SimpleTransmission</type>
        <joint name="wheel_3_joint">
            <hardwareInterface>hardware_interface/ActuatorInterface</hardwareInterface>
        </joint>
        <actuator name="motor_3">
            <hardwareInterface>hardware_interface/ActuatorInterface</hardwareInterface>
            <mechanicalReduction>1</mechanicalReduction>
        </actuator>
    </transmission>

    <gazebo>
        <plugin name="gazebo_ros2_control" filename="libgazebo_ros2_control.so">
        </plugin>
    </gazebo>

</robot>
